Workbook

Sheet רשימת ילדים והורים
A1: שם תלמיד | B1: כיתת אם | C1: ישוב | D1: אב | E1: נייד | F1: אם | G1: נייד 2
A2: אוזרסקי קורן ים | B2: א' - 1 | C2: דבירה | D2: ודים | E2: 054-5984412 | F2: ירדן | G2: 054-7916961
A3: אטיאס אליה | B3: א' - 2 | C3: דבירה | D3: יקיר | E3: 054-6666928 | F3: גל | G3: 054-7000690
A4: איאש הדס | B4: א' - 1 | C4: דבירה | D4: אביתר | E4: 052-2624333 | F4: מיכל | G4: 054-8060750
A5: אליהו איתי | B5: א' - 2 | C5: דבירה | D5: הדר | E5: 050-6363636 | F5: לימור | G5: 052-8340912
A6: אמיתי אופיר | B6: א' - 1 | C6: דבירה | D6: ניצן | E6: 052-8105335 | F6: סיון | G6: 054-4666337
A7: בנאי אורי | B7: א' - 1 | C7: דבירה | D7: אהוד | E7: 052-8105314 | F7: הדר | G7: 054-260-8250
A8: בשן נגה | B8: א' - 2 | C8: דבירה | D8: חנן | E8: 052-5306172 | F8: שרון | G8: 050-8444188
A9: גולדפרב רפאל | B9: א' - 2 | C9: דבירה | D9: שימי | E9: 054-5869203 | F9: אורטל | G9: 052-6671235
A10: ויסברג עדי | B10: א' - 2 | C10: דבירה | D10: איתי | E10: 054-2228232 | F10: איילת צי | G10: 054-2228232
A11: זר דריה אירית | B11: א' - 1 | C11: דבירה | D11: נפתלי אליעזר | E11: 054-5851580 | F11: עדן | G11: 052-8105484
A12: כרמל עלמא | B12: א' - 2 | C12: דבירה | D12: אלעד | E12: 050-8335225 | F12: מיכל | G12: 050-4899495
... A20: פוגל יצחקי אופק | B20: א' - 1 | C20: דבירה | D20: שלומי | E20: 052-4836462 | F20: מיכל | G20: 050-789-0007
A21: פונגסידה עלמא ג'נט | B21: א' - 2 | C21: דבירה | D21: סאווירט | F21: שי | G21: 052-8105542
A22: פרץ רני | B22: א' - 2 | C22: דבירה | D22: דניאל | E22: 052-7213203 | F22: נואי | G22: 053-4205629
A23: קלפון דור | B23: א' - 2 | C23: דבירה | D23: אליאב | E23: 050-5065453 | F23: אורית | G23: 052-8105211
A24: רובין אביב | B24: א' - 1 | C24: דבירה | D24: ראם | E24: 050-7681666 | F24: הילה | G24: 052-8280929
A25: שטוטמן אורי | B25: א' - 1 | C25: דבירה | D25: יניר | E25: 052-5409995 | F25: ליאורה ר | G25: 052-2249900
A26: שראייר יהונתן | B26: א' - 1 | C26: דבירה | D26: יואב | E26: 054-4978052 | F26: שירן טובה | G26: 052-6446282
A27: בוסיבא שי-לי | B27: ב' - 1 | C27: דבירה | D27: ליאת | E27: 054-3010207
A28: בנימין יובל דויד | B28: ב' - 1 | C28: דבירה | D28: יונתן לואיס | E28: 050-7306010 | F28: הדס | G28: 050-7306010
A29: בקון עמית | B29: ב' - 1 | C29: דבירה | D29: דקל | E29: 052-9452163 | F29: מור | G29: 052-9452163 ,052-3640321
A30: טליאס גיא מאיר | B30: ב' - 1 | C30: דבירה | D30: תמיר | E30: 052-8105276 | F30: צליל | G30: 050-6598334
A31: כהן איתי | B31: ב' - 1 | C31: דבירה | D31: עפר | E31: 052-7482843 | F31: יעל | G31: 054-2459124
A32: להב אורי | B32: ב' - 1 | C32: דבירה | D32: ערן (דוד | E32: 054-2561461 | F32: יערה | G32: 058-6862244
A33: לוין רונה | B33: ב' - 1 | C33: דבירה | D33: ליאור | E33: 052-8105283 | F33: ברית | G33: 054-5292052
A34: פרידמן רני | B34: ב' - 1 | C34: דבירה | D34: ברק | E34: 054-3452770 | F34: שניר | G34: 054-9009033
A35: קרואני עידן אייל | B35: ב' - 1 | C35: דבירה | D35: שגיא | E35: 052-8105494 | F35: דנה | G35: 054-6317282
A36: בלקין פרדו ב מתיאו | B36: ב' - 2 | C36: דבירה | D36: מרסלו | E36: 050-8843020 | F36: מילנה | G36: 058-6669293
A37: בן יוסף עומר | B37: ב' - 2 | C37: דבירה | D37: יפתח | E37: 054-6616410 | F37: נטלי | G37: 052-5361939
A38: גבע מאיה | B38: ב' - 2 | C38: דבירה | D38: ים | E38: 054-5665800 | F38: מיטל אליס | G38: 054-5715432
A39: גוטמן תומר | B39: ב' - 2 | C39: דבירה | D39: נמרוד | E39: 050-2034347 | F39: אפרת | G39: 050-4417715
... A49: כהן ינאי | B49: ג' - 1 | C49: דבירה | D49: יהודה או | E49: 054-4882230 | F49: אסתי | G49: 052-7798329
A50: נאור עומר | B50: ג' - 1 | C50: דבירה | D50: אחיקם | F50: ליטל | G50: 054-4563069
A51: פארן עלמה | B51: ג' - 1 | C51: דבירה | D51: נוה | E51: 052-2372567 | F51: אפרת | G51: 050-4443636
A52: שני אייל | B52: ג' - 1 | C52: דבירה | D52: ינאי | E52: 052-8105315 | F52: אביגל | G52: 052-6015363
A53: אטיאס רפאל | B53: ג' - 2 | C53: דבירה | D53: יקיר | E53: 054-6666928 | F53: גל | G53: 054-7000690
A54: אפללו יובל זיוה | B54: ג' - 2 | C54: דבירה | D54: יגאל | E54: 050-5679383 | F54: אפרת | G54: 054-4874988
A55: בירקנפלד אביב | B55: ג' - 2 | C55: דבירה | D55: גל | E55: 052-4708771 | F55: לילי | G55: 052-4708771
A56: בכר ניצן | B56: ג' - 2 | C56: דבירה | D56: אביעד | E56: 050-6312674 | F56: נופר | G56: 052-8105368
...

Sheet לוח הסעות מוצע
A1: תאריך | B1: משמרת | C1: הסעה 1 (א-ב) | D1: הסעה 2 (ג-ו) | E1: הסעה 3 (ד-ה) | F1: רכב מסיע
A2: 46269 | B2: בוקר | C2: דוידסון - רונן אנד/עמית | D2: כהן - יהודה או/אסתי | E2: אפרתי - נעם/המיה | F2: סקג'ו - איל/שירן
A3: 46269 | B3: צהריים | C3: שטוטמן - יניר/ליאורה ר | D3: בן יוסף - יפתח/נטלי | E3: נאור - אחיקם/ליטל | F3: ירון - איתמר/יעל
A4: 46283 | B4: בוקר | C4: פרץ - דניאל/נואי | D4: פרילוצקי - רומן ישר/אינה | E4: ויסברג - איתי/איילת צי | F4: פונגסידה עלמא - סאווירט/שי
A5: 46283 | B5: צהריים | C5: בשן - חנן/שרון | D5: חזן - גיא/נועה סול | E5: ז'נסקר פז - אדוארד/הילה | F5: רבינס - רונן/מאיה
A6: 46304 | B6: בוקר | C6: גבע - ים/מיטל אליס | D6: טל - דרור/אלינור | E6: כהן - עפר/יעל | F6: שראייר - יואב/שירן טובה
A7: 46304 | B7: צהריים | C7: פוגל יצחקי - שלומי/מיכל | D7: איאש - אביתר/מיכל | E7: פרי - שלומי/איסי לי | F7: פרידמן אהרון - עודד/מיכל
A8: 46311 | B8: בוקר | C8: סקג'ו - איל/שירן | D8: הדס - אלדד/אנה | E8: חדד - משה/רחל | F8: שדמי חיון - ליאור/רוני
A9: 46311 | B9: צהריים | C9: להב - ערן (דוד/יערה | D9: קלפון - אליאב/אורית | E9: בן דור - עומר טל | F9: פארן - נוה/אפרת
A10: 46318 | B10: בוקר | C10: גולדפרב - שימי/אורטל | D10: בירקנפלד - גל/לילי | E10: יצחקי - אהוד/מורן | F10: שואף - נדב/ציפי
A11: 46318 | B11: צהריים | C11: בנימין - יונתן לואיס/הדס | D11: מולכו - נועם/אנטל | E11: גור - ינון/מיטל | F11: ברטוב - שי/אורלי דב
A12: 46325 | B12: בוקר | C12: פרידמן - ברק/שניר | D12: אפללו - יגאל/אפרת | E12: הררי - אורי/חן מלי | F12: בנאי - אהוד/הדר
A13: 46325 | B13: צהריים | C13: גוטמן - נמרוד/אפרת | D13: דוידי - יגאל/הילה | E13: גונן - לירון/אולגה | F13: כהן - מתן/רותם
... A73: 46563 | B73: צהריים | C73: כרמל - אלעד/מיכל | D73: פריד - אמיר יעק/טלי | E73: רפפורט - אביב/ענת | F73: ווינטראוב - אורן נחמן/קרן

Sheet עזר
A1: משפחה | B1: תאריך | C1: מונה | D1: מפתח | E1: משמרת | F1: סוג תפקיד
A2: ='לוח הסעות מוצע'!C2 -> דוידסון - רונן אנד/עמית | B2: ='לוח הסעות מוצע'!A2 -> 46269 | C2: =COUNTIF($A$2:A2,A2) -> 1 | D2: =A2&"|"&C2 -> דוידסון - רונן אנד/עמית|1 | E2: ='לוח הסעות מוצע'!B2 -> בוקר | F2: הסעה
A3: ='לוח הסעות מוצע'!D2 -> כהן - יהודה או/אסתי | B3: ='לוח הסעות מוצע'!A2 -> 46269 | C3: =COUNTIF($A$2:A3,A3) -> 1 | D3: =A3&"|"&C3 -> כהן - יהודה או/אסתי|1 | E3: ='לוח הסעות מוצע'!B2 -> בוקר | F3: הסעה
A4: ='לוח הסעות מוצע'!E2 -> אפרתי - נעם/המיה | B4: ='לוח הסעות מוצע'!A2 -> 46269 | C4: =COUNTIF($A$2:A4,A4) -> 1 | D4: =A4&"|"&C4 -> אפרתי - נעם/המיה|1 | E4: ='לוח הסעות מוצע'!B2 -> בוקר | F4: הסעה
A5: ='לוח הסעות מוצע'!F2 -> סקג'ו - איל/שירן | B5: ='לוח הסעות מוצע'!A2 -> 46269 | C5: =COUNTIF($A$2:A5,A5) -> 1 | D5: =A5&"|"&C5 -> סקג'ו - איל/שירן|1 | E5: ='לוח הסעות מוצע'!B2 -> בוקר | F5: רכב
A6: ='לוח הסעות מוצע'!C3 -> שטוטמן - יניר/ליאורה ר | B6: ='לוח הסעות מוצע'!A3 -> 46269 | C6: =COUNTIF($A$2:A6,A6) -> 1 | D6: =A6&"|"&C6 -> שטוטמן - יניר/ליאורה ר|1 | E6: ='לוח הסעות מוצע'!B3 -> צהריים | F6: הסעה
A7: ='לוח הסעות מוצע'!D3 -> בן יוסף - יפתח/נטלי | B7: ='לוח הסעות מוצע'!A3 -> 46269 | C7: =COUNTIF($A$2:A7,A7) -> 1 | D7: =A7&"|"&C7 -> בן יוסף - יפתח/נטלי|1 | E7: ='לוח הסעות מוצע'!B3 -> צהריים | F7: הסעה
A8: ='לוח הסעות מוצע'!E3 -> נאור - אחיקם/ליטל | B8: ='לוח הסעות מוצע'!A3 -> 46269 | C8: =COUNTIF($A$2:A8,A8) -> 1 | D8: =A8&"|"&C8 -> נאור - אחיקם/ליטל|1 | E8: ='לוח הסעות מוצע'!B3 -> צהריים | F8: הסעה
A9: ='לוח הסעות מוצע'!F3 -> ירון - איתמר/יעל | B9: ='לוח הסעות מוצע'!A3 -> 46269 | C9: =COUNTIF($A$2:A9,A9) -> 1 | D9: =A9&"|"&C9 -> ירון - איתמר/יעל|1 | E9: ='לוח הסעות מוצע'!B3 -> צהריים | F9: רכב
A10: ='לוח הסעות מוצע'!C4 -> פרץ - דניאל/נואי | B10: ='לוח הסעות מוצע'!A4 -> 46283 | C10: =COUNTIF($A$2:A10,A10) -> 1 | D10: =A10&"|"&C10 -> פרץ - דניאל/נואי|1 | E10: ='לוח הסעות מוצע'!B4 -> בוקר | F10: הסעה
A11: ='לוח הסעות מוצע'!D4 -> פרילוצקי - רומן ישר/אינה | B11: ='לוח הסעות מוצע'!A4 -> 46283 | C11: =COUNTIF($A$2:A11,A11) -> 1 | D11: =A11&"|"&C11 -> פרילוצקי - רומן ישר/אינה|1 | E11: ='לוח הסעות מוצע'!B4 -> בוקר | F11: הסעה
A12: ='לוח הסעות מוצע'!E4 -> ויסברג - איתי/איילת צי | B12: ='לוח הסעות מוצע'!A4 -> 46283 | C12: =COUNTIF($A$2:A12,A12) -> 1 | D12: =A12&"|"&C12 -> ויסברג - איתי/איילת צי|1 | E12: ='לוח הסעות מוצע'!B4 -> בוקר | F12: הסעה
A13: ='לוח הסעות מוצע'!F4 -> פונגסידה עלמא - סאווירט/שי | B13: ='לוח הסעות מוצע'!A4 -> 46283 | C13: =COUNTIF($A$2:A13,A13) -> 1 | D13: =A13&"|"&C13 -> פונגסידה עלמא - סאווירט/שי|1 | E13: ='לוח הסעות מוצע'!B4 -> בוקר | F13: רכב
A14: ='לוח הסעות מוצע'!C5 -> בשן - חנן/שרון | B14: ='לוח הסעות מוצע'!A5 -> 46283 | C14: =COUNTIF($A$2:A14,A14) -> 1 | D14: =A14&"|"&C14 -> בשן - חנן/שרון|1 | E14: ='לוח הסעות מוצע'!B5 -> צהריים | F14: הסעה
A15: ='לוח הסעות מוצע'!D5 -> חזן - גיא/נועה סול | B15: ='לוח הסעות מוצע'!A5 -> 46283 | C15: =COUNTIF($A$2:A15,A15) -> 1 | D15: =A15&"|"&C15 -> חזן - גיא/נועה סול|1 | E15: ='לוח הסעות מוצע'!B5 -> צהריים | F15: הסעה
A16: ='לוח הסעות מוצע'!E5 -> ז'נסקר פז - אדוארד/הילה | B16: ='לוח הסעות מוצע'!A5 -> 46283 | C16: =COUNTIF($A$2:A16,A16) -> 1 | D16: =A16&"|"&C16 -> ז'נסקר פז - אדוארד/הילה|1 | E16: ='לוח הסעות מוצע'!B5 -> צהריים | F16: הסעה
A17: ='לוח הסעות מוצע'!F5 -> רבינס - רונן/מאיה | B17: ='לוח הסעות מוצע'!A5 -> 46283 | C17: =COUNTIF($A$2:A17,A17) -> 1 | D17: =A17&"|"&C17 -> רבינס - רונן/מאיה|1 | E17: ='לוח הסעות מוצע'!B5 -> צהריים | F17: רכב
A18: ='לוח הסעות מוצע'!C6 -> גבע - ים/מיטל אליס | B18: ='לוח הסעות מוצע'!A6 -> 46304 | C18: =COUNTIF($A$2:A18,A18) -> 1 | D18: =A18&"|"&C18 -> גבע - ים/מיטל אליס|1 | E18: ='לוח הסעות מוצע'!B6 -> בוקר | F18: הסעה
A19: ='לוח הסעות מוצע'!D6 -> טל - דרור/אלינור | B19: ='לוח הסעות מוצע'!A6 -> 46304 | C19: =COUNTIF($A$2:A19,A19) -> 1 | D19: =A19&"|"&C19 -> טל - דרור/אלינור|1 | E19: ='לוח הסעות מוצע'!B6 -> בוקר | F19: הסעה
A20: ='לוח הסעות מוצע'!E6 -> כהן - עפר/יעל | B20: ='לוח הסעות מוצע'!A6 -> 46304 | C20: =COUNTIF($A$2:A20,A20) -> 1 | D20: =A20&"|"&C20 -> כהן - עפר/יעל|1 | E20: ='לוח הסעות מוצע'!B6 -> בוקר | F20: הסעה
A21: ='לוח הסעות מוצע'!F6 -> שראייר - יואב/שירן טובה | B21: ='לוח הסעות מוצע'!A6 -> 46304 | C21: =COUNTIF($A$2:A21,A21) -> 1 | D21: =A21&"|"&C21 -> שראייר - יואב/שירן טובה|1 | E21: ='לוח הסעות מוצע'!B6 -> בוקר | F21: רכב
A22: ='לוח הסעות מוצע'!C7 -> פוגל יצחקי - שלומי/מיכל | B22: ='לוח הסעות מוצע'!A7 -> 46304 | C22: =COUNTIF($A$2:A22,A22) -> 1 | D22: =A22&"|"&C22 -> פוגל יצחקי - שלומי/מיכל|1 | E22: ='לוח הסעות מוצע'!B7 -> צהריים | F22: הסעה
A23: ='לוח הסעות מוצע'!D7 -> איאש - אביתר/מיכל | B23: ='לוח הסעות מוצע'!A7 -> 46304 | C23: =COUNTIF($A$2:A23,A23) -> 1 | D23: =A23&"|"&C23 -> איאש - אביתר/מיכל|1 | E23: ='לוח הסעות מוצע'!B7 -> צהריים | F23: הסעה
A24: ='לוח הסעות מוצע'!E7 -> פרי - שלומי/איסי לי | B24: ='לוח הסעות מוצע'!A7 -> 46304 | C24: =COUNTIF($A$2:A24,A24) -> 1 | D24: =A24&"|"&C24 -> פרי - שלומי/איסי לי|1 | E24: ='לוח הסעות מוצע'!B7 -> צהריים | F24: הסעה
A25: ='לוח הסעות מוצע'!F7 -> פרידמן אהרון - עודד/מיכל | B25: ='לוח הסעות מוצע'!A7 -> 46304 | C25: =COUNTIF($A$2:A25,A25) -> 1 | D25: =A25&"|"&C25 -> פרידמן אהרון - עודד/מיכל|1 | E25: ='לוח הסעות מוצע'!B7 -> צהריים | F25: רכב
A26: ='לוח הסעות מוצע'!C8 -> סקג'ו - איל/שירן | B26: ='לוח הסעות מוצע'!A8 -> 46311 | C26: =COUNTIF($A$2:A26,A26) -> 2 | D26: =A26&"|"&C26 -> סקג'ו - איל/שירן|2 | E26: ='לוח הסעות מוצע'!B8 -> בוקר | F26: הסעה
A27: ='לוח הסעות מוצע'!D8 -> הדס - אלדד/אנה | B27: ='לוח הסעות מוצע'!A8 -> 46311 | C27: =COUNTIF($A$2:A27,A27) -> 1 | D27: =A27&"|"&C27 -> הדס - אלדד/אנה|1 | E27: ='לוח הסעות מוצע'!B8 -> בוקר | F27: הסעה
A28: ='לוח הסעות מוצע'!E8 -> חדד - משה/רחל | B28: ='לוח הסעות מוצע'!A8 -> 46311 | C28: =COUNTIF($A$2:A28,A28) -> 1 | D28: =A28&"|"&C28 -> חדד - משה/רחל|1 | E28: ='לוח הסעות מוצע'!B8 -> בוקר | F28: הסעה
A29: ='לוח הסעות מוצע'!F8 -> שדמי חיון - ליאור/רוני | B29: ='לוח הסעות מוצע'!A8 -> 46311 | C29: =COUNTIF($A$2:A29,A29) -> 1 | D29: =A29&"|"&C29 -> שדמי חיון - ליאור/רוני|1 | E29: ='לוח הסעות מוצע'!B8 -> בוקר | F29: רכב
A30: ='לוח הסעות מוצע'!C9 -> להב - ערן (דוד/יערה | B30: ='לוח הסעות מוצע'!A9 -> 46311 | C30: =COUNTIF($A$2:A30,A30) -> 1 | D30: =A30&"|"&C30 -> להב - ערן (דוד/יערה|1 | E30: ='לוח הסעות מוצע'!B9 -> צהריים | F30: הסעה
A31: ='לוח הסעות מוצע'!D9 -> קלפון - אליאב/אורית | B31: ='לוח הסעות מוצע'!A9 -> 46311 | C31: =COUNTIF($A$2:A31,A31) -> 1 | D31: =A31&"|"&C31 -> קלפון - אליאב/אורית|1 | E31: ='לוח הסעות מוצע'!B9 -> צהריים | F31: הסעה
A32: ='לוח הסעות מוצע'!E9 -> בן דור - עומר טל | B32: ='לוח הסעות מוצע'!A9 -> 46311 | C32: =COUNTIF($A$2:A32,A32) -> 1 | D32: =A32&"|"&C32 -> בן דור - עומר טל|1 | E32: ='לוח הסעות מוצע'!B9 -> צהריים | F32: הסעה
A33: ='לוח הסעות מוצע'!F9 -> פארן - נוה/אפרת | B33: ='לוח הסעות מוצע'!A9 -> 46311 | C33: =COUNTIF($A$2:A33,A33) -> 1 | D33: =A33&"|"&C33 -> פארן - נוה/אפרת|1 | E33: ='לוח הסעות מוצע'!B9 -> צהריים | F33: רכב
A34: ='לוח הסעות מוצע'!C10 -> גולדפרב - שימי/אורטל | B34: ='לוח הסעות מוצע'!A10 -> 46318 | C34: =COUNTIF($A$2:A34,A34) -> 1 | D34: =A34&"|"&C34 -> גולדפרב - שימי/אורטל|1 | E34: ='לוח הסעות מוצע'!B10 -> בוקר | F34: הסעה
A35: ='לוח הסעות מוצע'!D10 -> בירקנפלד - גל/לילי | B35: ='לוח הסעות מוצע'!A10 -> 46318 | C35: =COUNTIF($A$2:A35,A35) -> 1 | D35: =A35&"|"&C35 -> בירקנפלד - גל/לילי|1 | E35: ='לוח הסעות מוצע'!B10 -> בוקר | F35: הסעה
A36: ='לוח הסעות מוצע'!E10 -> יצחקי - אהוד/מורן | B36: ='לוח הסעות מוצע'!A10 -> 46318 | C36: =COUNTIF($A$2:A36,A36) -> 1 | D36: =A36&"|"&C36 -> יצחקי - אהוד/מורן|1 | E36: ='לוח הסעות מוצע'!B10 -> בוקר | F36: הסעה
A37: ='לוח הסעות מוצע'!F10 -> שואף - נדב/ציפי | B37: ='לוח הסעות מוצע'!A10 -> 46318 | C37: =COUNTIF($A$2:A37,A37) -> 1 | D37: =A37&"|"&C37 -> שואף - נדב/ציפי|1 | E37: ='לוח הסעות מוצע'!B10 -> בוקר | F37: רכב
A38: ='לוח הסעות מוצע'!C11 -> בנימין - יונתן לואיס/הדס | B38: ='לוח הסעות מוצע'!A11 -> 46318 | C38: =COUNTIF($A$2:A38,A38) -> 1 | D38: =A38&"|"&C38 -> בנימין - יונתן לואיס/הדס|1 | E38: ='לוח הסעות מוצע'!B11 -> צהריים | F38: הסעה
A39: ='לוח הסעות מוצע'!D11 -> מולכו - נועם/אנטל | B39: ='לוח הסעות מוצע'!A11 -> 46318 | C39: =COUNTIF($A$2:A39,A39) -> 1 | D39: =A39&"|"&C39 -> מולכו - נועם/אנטל|1 | E39: ='לוח הסעות מוצע'!B11 -> צהריים | F39: הסעה
A40: ='לוח הסעות מוצע'!E11 -> גור - ינון/מיטל | B40: ='לוח הסעות מוצע'!A11 -> 46318 | C40: =COUNTIF($A$2:A40,A40) -> 1 | D40: =A40&"|"&C40 -> גור - ינון/מיטל|1 | E40: ='לוח הסעות מוצע'!B11 -> צהריים | F40: הסעה
...

Sheet ספירת הסעות למשפחה
A1: משפחה | B1: מספר הסעות | C1: בוקר | D1: צהריים | E1: הסעה | F1: רכב | G1: תאריך 1 | H1: תאריך 2 | I1: תאריך 3
A2: אגאי - ערן/ליאת | B2: =COUNTIF(עזר!$A$2:$A$289,$A2) -> 3 | C2: =COUNTIFS(עזר!$A$2:$A$289,$A2,עזר!$E$2:$E$289,"בוקר") -> 1 | D2: =COUNTIFS(עזר!$A$2:$A$289,$A2,עזר!$E$2:$E$289,"צהריים") -> 2 | E2: =COUNTIFS(עזר!$A$2:$A$289,$A2,עזר!$F$2:$F$289,"הסעה") -> 2 | F2: =COUNTIFS(עזר!$A$2:$A$289,$A2,עזר!$F$2:$F$289,"רכב") -> 1 | G2: =IFERROR(INDEX(עזר!$B$2:$B$289,MATCH($A2&"|1",עזר!$D$2:$D$289,0)),"") -> 46353 | H2: =IFERROR(INDEX(עזר!$B$2:$B$289,MATCH($A2&"|2",עזר!$D$2:$D$289,0)),"") -> 46444 | I2: =IFERROR(INDEX(עזר!$B$2:$B$289,MATCH($A2&"|3",עזר!$D$2:$D$289,0)),"") -> 46542
A3: אוזרסקי - ודים/ירדן | B3: =COUNTIF(עזר!$A$2:$A$289,$A3) -> 2 | C3: =COUNTIFS(עזר!$A$2:$A$289,$A3,עזר!$E$2:$E$289,"בוקר") -> 1 | D3: =COUNTIFS(עזר!$A$2:$A$289,$A3,עזר!$E$2:$E$289,"צהריים") -> 1 | E3: =COUNTIFS(עזר!$A$2:$A$289,$A3,עזר!$F$2:$F$289,"הסעה") -> 2 | F3: =COUNTIFS(עזר!$A$2:$A$289,$A3,עזר!$F$2:$F$289,"רכב") -> 0 | G3: =IFERROR(INDEX(עזר!$B$2:$B$289,MATCH($A3&"|1",עזר!$D$2:$D$289,0)),"") -> 46437 | H3: =IFERROR(INDEX(עזר!$B$2:$B$289,MATCH($A3&"|2",עזר!$D$2:$D$289,0)),"") -> 46556 | I3: =IFERROR(INDEX(עזר!$B$2:$B$289,MATCH($A3&"|3",עזר!$D$2:$D$289,0)),"")
A4: אטיאס - יקיר/גל | B4: =COUNTIF(עזר!$A$2:$A$289,$A4) -> 3 | C4: =COUNTIFS(עזר!$A$2:$A$289,$A4,עזר!$E$2:$E$289,"בוקר") -> 2 | D4: =COUNTIFS(עזר!$A$2:$A$289,$A4,עזר!$E$2:$E$289,"צהריים") -> 1 | E4: =COUNTIFS(עזר!$A$2:$A$289,$A4,עזר!$F$2:$F$289,"הסעה") -> 2 | F4: =COUNTIFS(עזר!$A$2:$A$289,$A4,עזר!$F$2:$F$289,"רכב") -> 1 | G4: =IFERROR(INDEX(עזר!$B$2:$B$289,MATCH($A4&"|1",עזר!$D$2:$D$289,0)),"") -> 46339 | H4: =IFERROR(INDEX(עזר!$B$2:$B$289,MATCH($A4&"|2",עזר!$D$2:$D$289,0)),"") -> 46437 | I4: =IFERROR(INDEX(עזר!$B$2:$B$289,MATCH($A4&"|3",עזר!$D$2:$D$289,0)),"") -> 46479
A5: איאש - אביתר/מיכל | B5: =COUNTIF(עזר!$A$2:$A$289,$A5) -> 3 | C5: =COUNTIFS(עזר!$A$2:$A$289,$A5,עזר!$E$2:$E$289,"בוקר") -> 1 | D5: =COUNTIFS(עזר!$A$2:$A$289,$A5,עזר!$E$2:$E$289,"צהריים") -> 2 | E5: =COUNTIFS(עזר!$A$2:$A$289,$A5,עזר!$F$2:$F$289,"הסעה") -> 2 | F5: =COUNTIFS(עזר!$A$2:$A$289,$A5,עזר!$F$2:$F$289,"רכב") -> 1 | G5: =IFERROR(INDEX(עזר!$B$2:$B$289,MATCH($A5&"|1",עזר!$D$2:$D$289,0)),"") -> 46304 | H5: =IFERROR(INDEX(עזר!$B$2:$B$289,MATCH($A5&"|2",עזר!$D$2:$D$289,0)),"") -> 46395 | I5: =IFERROR(INDEX(עזר!$B$2:$B$289,MATCH($A5&"|3",עזר!$D$2:$D$289,0)),"") -> 46486
A6: אל אל - שרון/סיון | B6: =COUNTIF(עזר!$A$2:$A$289,$A6) -> 3 | C6: =COUNTIFS(עזר!$A$2:$A$289,$A6,עזר!$E$2:$E$289,"בוקר") -> 1 | D6: =COUNTIFS(עזר!$A$2:$A$289,$A6,עזר!$E$2:$E$289,"צהריים") -> 2 | E6: =COUNTIFS(עזר!$A$2:$A$289,$A6,עזר!$F$2:$F$289,"הסעה") -> 2 | F6: =COUNTIFS(עזר!$A$2:$A$289,$A6,עזר!$F$2:$F$289,"רכב") -> 1 | G6: =IFERROR(INDEX(עזר!$B$2:$B$289,MATCH($A6&"|1",עזר!$D$2:$D$289,0)),"") -> 46346 | H6: =IFERROR(INDEX(עזר!$B$2:$B$289,MATCH($A6&"|2",עזר!$D$2:$D$289,0)),"") -> 46437 | I6: =IFERROR(INDEX(עזר!$B$2:$B$289,MATCH($A6&"|3",עזר!$D$2:$D$289,0)),"") -> 46542
A7: אליהו - הדר/לימור | B7: =COUNTIF(עזר!$A$2:$A$289,$A7) -> 3 | C7: =COUNTIFS(עזר!$A$2:$A$289,$A7,עזר!$E$2:$E$289,"בוקר") -> 1 | D7: =COUNTIFS(עזר!$A$2:$A$289,$A7,עזר!$E$2:$E$289,"צהריים") -> 2 | E7: =COUNTIFS(עזר!$A$2:$A$289,$A7,עזר!$F$2:$F$289,"הסעה") -> 3 | F7: =COUNTIFS(עזר!$A$2:$A$289,$A7,עזר!$F$2:$F$289,"רכב") -> 0 | G7: =IFERROR(INDEX(עזר!$B$2:$B$289,MATCH($A7&"|1",עזר!$D$2:$D$289,0)),"") -> 46332 | H7: =IFERROR(INDEX(עזר!$B$2:$B$289,MATCH($A7&"|2",עזר!$D$2:$D$289,0)),"") -> 46430 | I7: =IFERROR(INDEX(עזר!$B$2:$B$289,MATCH($A7&"|3",עזר!$D$2:$D$289,0)),"") -> 46535
A8: אלימלך - דור/רות | B8: =COUNTIF(עזר!$A$2:$A$289,$A8) -> 2 | C8: =COUNTIFS(עזר!$A$2:$A$289,$A8,עזר!$E$2:$E$289,"בוקר") -> 1 | D8: =COUNTIFS(עזר!$A$2:$A$289,$A8,עזר!$E$2:$E$289,"צהריים") -> 1 | E8: =COUNTIFS(עזר!$A$2:$A$289,$A8,עזר!$F$2:$F$289,"הסעה") -> 2 | F8: =COUNTIFS(עזר!$A$2:$A$289,$A8,עזר!$F$2:$F$289,"רכב") -> 0 | G8: =IFERROR(INDEX(עזר!$B$2:$B$289,MATCH($A8&"|1",עזר!$D$2:$D$289,0)),"") -> 46381 | H8: =IFERROR(INDEX(עזר!$B$2:$B$289,MATCH($A8&"|2",עזר!$D$2:$D$289,0)),"") -> 46465 | I8: =IFERROR(INDEX(עזר!$B$2:$B$289,MATCH($A8&"|3",עזר!$D$2:$D$289,0)),"")
A9: אמיתי - ניצן/סיון | B9: =COUNTIF(עזר!$A$2:$A$289,$A9) -> 3 | C9: =COUNTIFS(עזר!$A$2:$A$289,$A9,עזר!$E$2:$E$289,"בוקר") -> 2 | D9: =COUNTIFS(עזר!$A$2:$A$289,$A9,עזר!$E$2:$E$289,"צהריים") -> 1 | E9: =COUNTIFS(עזר!$A$2:$A$289,$A9,עזר!$F$2:$F$289,"הסעה") -> 3 | F9: =COUNTIFS(עזר!$A$2:$A$289,$A9,עזר!$F$2:$F$289,"רכב") -> 0 | G9: =IFERROR(INDEX(עזר!$B$2:$B$289,MATCH($A9&"|1",עזר!$D$2:$D$289,0)),"") -> 46346 | H9: =IFERROR(INDEX(עזר!$B$2:$B$289,MATCH($A9&"|2",עזר!$D$2:$D$289,0)),"") -> 46437 | I9: =IFERROR(INDEX(עזר!$B$2:$B$289,MATCH($A9&"|3",עזר!$D$2:$D$289,0)),"") -> 46542
A10: אנגלשטיין - דיו נויה | B10: =COUNTIF(עזר!$A$2:$A$289,$A10) -> 2 | C10: =COUNTIFS(עזר!$A$2:$A$289,$A10,עזר!$E$2:$E$289,"בוקר") -> 1 | D10: =COUNTIFS(עזר!$A$2:$A$289,$A10,עזר!$E$2:$E$289,"צהריים") -> 1 | E10: =COUNTIFS(עזר!$A$2:$A$289,$A10,עזר!$F$2:$F$289,"הסעה") -> 2 | F10: =COUNTIFS(עזר!$A$2:$A$289,$A10,עזר!$F$2:$F$289,"רכב") -> 0 | G10: =IFERROR(INDEX(עזר!$B$2:$B$289,MATCH($A10&"|1",עזר!$D$2:$D$289,0)),"") -> 46374 | H10: =IFERROR(INDEX(עזר!$B$2:$B$289,MATCH($A10&"|2",עזר!$D$2:$D$289,0)),"") -> 46423 | I10: =IFERROR(INDEX(עזר!$B$2:$B$289,MATCH($A10&"|3",עזר!$D$2:$D$289,0)),"")
A11: אפללו - יגאל/אפרת | B11: =COUNTIF(עזר!$A$2:$A$289,$A11) -> 3 | C11: =COUNTIFS(עזר!$A$2:$A$289,$A11,עזר!$E$2:$E$289,"בוקר") -> 1 | D11: =COUNTIFS(עזר!$A$2:$A$289,$A11,עזר!$E$2:$E$289,"צהריים") -> 2 | E11: =COUNTIFS(עזר!$A$2:$A$289,$A11,עזר!$F$2:$F$289,"הסעה") -> 3 | F11: =COUNTIFS(עזר!$A$2:$A$289,$A11,עזר!$F$2:$F$289,"רכב") -> 0 | G11: =IFERROR(INDEX(עזר!$B$2:$B$289,MATCH($A11&"|1",עזר!$D$2:$D$289,0)),"") -> 46325 | H11: =IFERROR(INDEX(עזר!$B$2:$B$289,MATCH($A11&"|2",עזר!$D$2:$D$289,0)),"") -> 46416 | I11: =IFERROR(INDEX(עזר!$B$2:$B$289,MATCH($A11&"|3",עזר!$D$2:$D$289,0)),"") -> 46528
A12: אפרתי - נעם/המיה | B12: =COUNTIF(עזר!$A$2:$A$289,$A12) -> 3 | C12: =COUNTIFS(עזר!$A$2:$A$289,$A12,עזר!$E$2:$E$289,"בוקר") -> 2 | D12: =COUNTIFS(עזר!$A$2:$A$289,$A12,עזר!$E$2:$E$289,"צהריים") -> 1 | E12: =COUNTIFS(עזר!$A$2:$A$289,$A12,עזר!$F$2:$F$289,"הסעה") -> 2 | F12: =COUNTIFS(עזר!$A$2:$A$289,$A12,עזר!$F$2:$F$289,"רכב") -> 1 | G12: =IFERROR(INDEX(עזר!$B$2:$B$289,MATCH($A12&"|1",עזר!$D$2:$D$289,0)),"") -> 46269 | H12: =IFERROR(INDEX(עזר!$B$2:$B$289,MATCH($A12&"|2",עזר!$D$2:$D$289,0)),"") -> 46381 | I12: =IFERROR(INDEX(עזר!$B$2:$B$289,MATCH($A12&"|3",עזר!$D$2:$D$289,0)),"") -> 46507
A13: אשכנזי אדלר - אוריה/מורן | B13: =COUNTIF(עזר!$A$2:$A$289,$A13) -> 2 | C13: =COUNTIFS(עזר!$A$2:$A$289,$A13,עזר!$E$2:$E$289,"בוקר") -> 1 | D13: =COUNTIFS(עזר!$A$2:$A$289,$A13,עזר!$E$2:$E$289,"צהריים") -> 1 | E13: =COUNTIFS(עזר!$A$2:$A$289,$A13,עזר!$F$2:$F$289,"הסעה") -> 2 | F13: =COUNTIFS(עזר!$A$2:$A$289,$A13,עזר!$F$2:$F$289,"רכב") -> 0 | G13: =IFERROR(INDEX(עזר!$B$2:$B$289,MATCH($A13&"|1",עזר!$D$2:$D$289,0)),"") -> 46360 | H13: =IFERROR(INDEX(עזר!$B$2:$B$289,MATCH($A13&"|2",עזר!$D$2:$D$289,0)),"") -> 46451 | I13: =IFERROR(INDEX(עזר!$B$2:$B$289,MATCH($A13&"|3",עזר!$D$2:$D$289,0)),"")
... A101: תורג'מן - עופר/הדס | B101: =COUNTIF(עזר!$A$2:$A$289,$A101) -> 3 | C101: =COUNTIFS(עזר!$A$2:$A$289,$A101,עזר!$E$2:$E$289,"בוקר") -> 2 | D101: =COUNTIFS(עזר!$A$2:$A$289,$A101,עזר!$E$2:$E$289,"צהריים") -> 1 | E101: =COUNTIFS(עזר!$A$2:$A$289,$A101,עזר!$F$2:$F$289,"הסעה") -> 1 | F101: =COUNTIFS(עזר!$A$2:$A$289,$A101,עזר!$F$2:$F$289,"רכב") -> 2 | G101: =IFERROR(INDEX(עזר!$B$2:$B$289,MATCH($A101&"|1",עזר!$D$2:$D$289,0)),"") -> 46332 | H101: =IFERROR(INDEX(עזר!$B$2:$B$289,MATCH($A101&"|2",עזר!$D$2:$D$289,0)),"") -> 46374 | I101: =IFERROR(INDEX(עזר!$B$2:$B$289,MATCH($A101&"|3",עזר!$D$2:$D$289,0)),"") -> 46465
